Workbook

Sheet ASVS Results
A1: Security Category | B1: Valid criteria | C1: Total criteria | D1: Validity Percentage | E1: ASVS Level Acquired
A2: Architecture, Design and Threat Modeling | B2: =0+COUNTIF('Architecture, Design and Threat'!G2:G45,"Valid") -> 33 | C2: =COUNTIF('Architecture, Design and Threat'!G2:G45,"<>Not Applicable") -> 39 | D2: =(B2/C2)*100 -> 84.615385 | F2: Diana
A3: Authentication | B3: =COUNTIF(Authentication!G2:G58,"Valid") -> 22 | C3: =COUNTIF(Authentication!G2:G58,"<>Not Applicable") -> 50 | D3: =(B3/C3)*100 -> 44 | F3: Diogo/Pedros
A4: Session Management | B4: =COUNTIF('Session Management'!G2:G21,"Valid") -> 13 | C4: =COUNTIF('Session Management'!G2:G21,"<>Not Applicable") -> 17 | D4: =(B4/C4)*100 -> 76.470588 | F4: Pedro C
A5: Access Control | B5: =COUNTIF('Access Control'!G2:G11,"Valid") -> 8 | C5: =COUNTIF('Access Control'!G2:G11,"<>Not Applicable") -> 9 | D5: =(B5/C5)*100 -> 88.888889 | F5: Pedro C
A6: Validation, Sanitization and Encoding | B6: =COUNTIF('Validation, Sanitization and En'!G2:G31,"Valid") -> 18 | C6: =COUNTIF('Validation, Sanitization and En'!G2:G31,"<>Not Applicable") -> 30 | D6: =(B6/C6)*100 -> 60 | F6: Pedro C
A7: Stored Cryptography | B7: =COUNTIF('Stored Cryptography'!G2:G17,"Valid") -> 8 | C7: =COUNTIF('Stored Cryptography'!G2:G17,"<>Not Applicable") -> 16 | D7: =(B7/C7)*100 -> 50 | F7: Diana
A8: Error Handling and Logging | B8: =COUNTIF('Error Handling and Logging'!G2:G14,"Valid") -> 7 | C8: =COUNTIF('Error Handling and Logging'!G2:G14,"<>Not Applicable") -> 12 | D8: =(B8/C8)*100 -> 58.333333 | F8: Diogo
A9: Data Protection | B9: =COUNTIF('Data Protection'!G2:G18,"Valid") -> 8 | C9: =COUNTIF('Data Protection'!G2:G18,"<>Not Applicable") -> 17 | D9: =(B9/C9)*100 -> 47.058824 | F9: Diogo
A10: Communication | B10: =COUNTIF(Communication!G2:G9,"Valid") -> 6 | C10: =COUNTIF(Communication!G2:G9,"<>Not Applicable") -> 8 | D10: =(B10/C10)*100 -> 75 | F10: Diogo
A11: Malicious Code | B11: =COUNTIF('Malicious Code'!G2:G11,"Valid") -> 7 | C11: =COUNTIF('Malicious Code'!G2:G11,"<>Not Applicable") -> 7 | D11: =(B11/C11)*100 -> 100 | F11: Pedro V
A12: Business Logic | B12: =COUNTIF('Business Logic'!G2:G9,"Valid") -> 5 | C12: =COUNTIF('Business Logic'!G2:G9,"<>Not Applicable") -> 8 | D12: =(B12/C12)*100 -> 62.5 | F12: Pedro V
A13: Files and Resources | B13: =COUNTIF('Files and Resources'!G2:G16,"Valid") -> 9 | C13: =COUNTIF('Files and Resources'!G2:G16,"<>Not Applicable") -> 13 | D13: =(B13/C13)*100 -> 69.230769 | F13: Pedro V
A14: API and Web Service | B14: =COUNTIF('API and Web Service'!G2:G16,"Valid") -> 8 | C14: =COUNTIF('API and Web Service'!G2:G16,"<>Not Applicable") -> 9 | D14: =(B14/C14)*100 -> 88.888889 | F14: Pedro V
A15: Configuration | B15: =COUNTIF(Configuration!G2:G26,"Valid") -> 18 | C15: =COUNTIF(Configuration!G2:G26,"<>Not Applicable") -> 23 | D15: =(B15/C15)*100 -> 78.26087 | F15: Diogo
A16: Total | B16: =SUM(B2:B15) -> 170 | C16: =SUM(C2:C15) -> 258 | D16: =(B16/C16)*100 -> 65.891473

Sheet Architecture, Design and Threat
A1: Area | B1: # | C1: ASVS Level | D1: CWE | E1: NIST | F1: Verification Requirement | G1: Valid | H1: Source Code Reference | I1: Comment | J1: Tool Used
A2: Secure Software Development Lifecycle | B2: 1.1.1 | C2: 2 | F2: Verify the use of a secure software development lifecycle that addresses security in all stages of development. ([C1](https://owasp.org/www-project-proactive-controls/#div-numbering)) | G2: Valid | H2: Relatório Fase 1 | I2: Ao longo de todos os sprints do projeto, a equipa tem realizado uma identificação contínua e sistemática dos aspetos de segurança relevantes para cada fase do desenvolvimento. Esta prática assegura que a segurança é considerada desde a conceção até à implementação, alinhando-se com as melhores práticas de um ciclo de vida de desenvolvimento seguro (SDLC). A modelação de ameaças, análise de riscos e definição de contramedidas são atividades integradas nas reuniões de planeamento e revisões, garantindo que potenciais vulnerabilidades são antecipadas e tratadas atempadamente.
B3: 1.1.2 | C3: 2 | D3: 1053 | F3: Verify the use of threat modeling for every design change or sprint planning to identify threats, plan for countermeasures, facilitate appropriate risk responses, and guide security testing. | G3: Valid | H3: Relatório Fase 1 | I3: A modelação de ameaças foi realizada na Fase 1 do projeto e continuará a ser efetuada nas fases seguintes e em cada alteração de design ou sprint, garantindo a identificação e mitigação contínua dos riscos de segurança.
B4: 1.1.3 | C4: 2 | D4: 1110 | F4: Verify that all user stories and features contain functional security constraints, such as "As a user, I should be able to view and edit my profile. I should not be able to view or edit anyone else's profile" | G4: Valid | H4: Relatório Fase 1 | I4: Para cada elemento do Diagrama de Fluxo de Dados (DFD) foram elaborados casos de abuso, identificando vetores de ataque e agentes de ameaça associados. Além disso, todas as user stories e funcionalidades incorporam restrições funcionais de segurança, assegurando que os requisitos de proteção são considerados desde a definição das funcionalidades. | J4: OWASP Threat Dragon - DFDs diagrams
B5: 1.1.4 | C5: 2 | D5: 1059 | F5: Verify documentation and justification of all the application's trust boundaries, components, and significant data flows. | G5: Valid | H5: Relatório Fase 1 | I5: Foram elaborados Diagramas de Fluxo de Dados (DFD) que indicam claramente as fronteiras de confiança, as ameaças associadas e o fluxo dos dados significativos no sistema. Esta documentação permite uma melhor compreensão e análise dos pontos críticos de segurança. | J5: OWASP Threat Dragon - DFDs diagrams
B6: 1.1.5 | C6: 2 | D6: 1059 | F6: Verify definition and security analysis of the application's high-level architecture and all connected remote services. ([C1](https://owasp.org/www-project-proactive-controls/#div-numbering)) | G6: Valid | H6: Fase 2 - Sprint 1 --> DTOS implementados | I6: Elaborámos diagramas de componentes e Diagramas de Fluxo de Dados (DFDs) e verificámos que a arquitetura do projeto não incluía Data Transfer Objects (DTOs). Por essa razão, a implementação dos DTOs foi realizada neste Sprint 1 da Fase 2, garantindo uma definição mais clara e segura da arquitetura de alto nível e dos serviços remotos associados.
B7: 1.1.6 | C7: 2 | D7: 637 | F7: Verify implementation of centralized, simple (economy of design), vetted, secure, and reusable security controls to avoid duplicate, missing, ineffective, or insecure controls. ([C10](https://owasp.org/www-project-proactive-controls/#div-numbering)) | G7: Valid | H7: Relatório Fase 1 | I7: Utilizamos sempre a mesma biblioteca para funções específicas, como autenticação e validação, garantindo a reutilização de código e a implementação de controlos de segurança centralizados, simples e seguros em todo o projeto.
B8: 1.1.7 | C8: 2 | D8: 637 | F8: Verify availability of a secure coding checklist, security requirements, guideline, or policy to all developers and testers. | G8: Valid | H8: Fase 2 - Sprint 1 | I8: Estamos a usar o ASVS como referência de segurança, integrado na pipeline de desenvolvimento e com revisões de código regulares, para garantir que todos seguem boas práticas de codificação segura. | J8: OWASP ASVS, GIT HUB
A9: Authentication Architecture | B9: 1.2.1 | C9: 2 | D9: 250 | F9: Verify the use of unique or special low-privilege operating system accounts for all application components, services, and servers. ([C3](https://owasp.org/www-project-proactive-controls/#div-numbering)) | G9: Valid | H9: Ainda não está completo, falta fazer o deploy na pipeline | I9: No estado atual, a pipeline CI/CD garante que as fases de build, teste e análise são executadas com permissões mínimas, conforme os runners da GitHub. No entanto, o passo de deploy ainda não está configurado para um ambiente real. Na fase seguinte, será necessário garantir que, em produção, os serviços correm com utilizadores com permissões limitadas
B10: 1.2.2 | C10: 2 | D10: 306 | F10: Verify that communications between application components, including APIs, middleware and data layers, are authenticated. Components should have the least necessary privileges needed. ([C3](https://owasp.org/www-project-proactive-controls/#div-numbering)) | G10: Valid | H10: appsettings.json: "ConnectionStrings": { "DefaultConnection": "Server=myserver;Database=mydb;User Id=myuser;Password=mypassword;" } | I10: A comunicação entre a aplicação e a base de dados é autenticada via connection string com credenciais específicas.
B11: 1.2.3 | C11: 2 | D11: 306 | F11: Verify that the application uses a single vetted authentication mechanism that is known to be secure, can be extended to include strong authentication, and has sufficient logging and monitoring to detect account abuse or breaches. | G11: Valid | H11: Colocar posteriormente logging para monitorizar. Program.cs: Autenticação por cookie: builder.Services.ConfigureApplicationCookie(options => { ... options.Cookie.SecurePolicy = CookieSecurePolicy.Always; options.Cookie.SameSite = SameSiteMode.Strict; }); Suporte a roles e política de autorização: builder.Services.AddAuthorization(options => { options.AddPolicy("Manager", policy => policy.RequireRole("Manager")); }); Suporte a extensibilidade via Identity: builder.Services.AddIdentity<AppUser, IdentityRole>() .AddEntityFrameworkStores<AppDbContext>() .AddDefaultTokenProviders(); | I11: Atualmente, a aplicação utiliza autenticação baseada em cookies com o ASP.NET Core Identity, um mecanismo seguro e extensível. Embora o sistema ainda não tenha um mecanismo de monitorização ativo, a arquitetura permite integrar facilmente logging e auditoria de acessos, através de ILogger, Application Insights, Serilog, ou outros sistemas compatíveis com .NET. A monitorização será considerada numa fase posterior do projeto. | J11: Identity (ASP.NET Core)
B12: 1.2.4 | C12: 2 | D12: 306 | F12: Verify that all authentication pathways and identity management APIs implement consistent authentication security control strength, such that there are no weaker alternatives per the risk of the application. | G12: Valid | H12: Program.cs: builder.Services.AddIdentity<AppUser, IdentityRole>() .AddEntityFrameworkStores<AppDbContext>() .AddDefaultTokenProviders(); builder.Services.ConfigureApplicationCookie(options => { options.LoginPath = "/api/account/login"; options.LogoutPath = "/api/account/logout"; options.SlidingExpiration = true; options.Cookie.SecurePolicy = CookieSecurePolicy.Always; options.Cookie.SameSite = SameSiteMode.Strict; }); | I12: Mecanismo de autenticação unificado e seguro com base em cookies. | J12: Identity (ASP.NET Core)
A13: Session Management Architecture | F13: This is a placeholder for future architectural requirements. | G13: Not Applicable
A14: Access Control Architecture | B14: 1.4.1 | C14: 2 | D14: 602 | F14: Verify that trusted enforcement points such as at access control gateways, servers, and serverless functions enforce access controls. Never enforce access controls on the client. | G14: Valid | H14: Program.cs and SubscriptionPeriodController.cs: // Em Program.cs: builder.Services.AddIdentity<AppUser, IdentityRole>() .AddEntityFrameworkStores<AppDbContext>() .AddDefaultTokenProviders(); // Configuração das policies: builder.Services.AddAuthorization(options => { options.AddPolicy("Manager", policy => policy.RequireRole("Manager")); options.AddPolicy("Producer", policy => policy.RequireRole("Producer")); options.AddPolicy("CoProducer", policy => policy.RequireRole("CoProducer")); }); // Middleware na pipeline: app.UseAuthentication(); app.UseAuthorization(); // No controller: [Authorize(Roles = nameof(UserType.Manager))] [HttpPost()] public async Task<IActionResult> CreateSubscriptionPeriodAndDeliveryDate(...) { // método protegido por policy de roles } | I14: Controlos de acesso aplicados exclusivamente no backend, usando middleware de autenticação/autorização e atributos [Authorize]. O frontend não valida permissões. | J14: ASP.NET Core Identity, Middleware ASP.NET Core
B15: 1.4.2 | C15: 2 | D15: 284 | F15: [DELETED, NOT ACTIONABLE] | G15: Not Applicable
B16: 1.4.3 | C16: 2 | D16: 272 | F16: [DELETED, DUPLICATE OF 4.1.3] | G16: Not Applicable
B17: 1.4.4 | C17: 2 | D17: 284 | F17: Verify the application uses a single and well-vetted access control mechanism for accessing protected data and resources. All requests must pass through this single mechanism to avoid copy and paste or insecure alternative paths. ([C7](https://owasp.org/www-project-proactive-controls/#div-numbering)) | G17: Valid | H17: Program.cs and SubscriptionPeriodController.cs. | I17: A aplicação assegura acesso uniforme através de Identity e políticas, evitando caminhos alternativos inseguros. | J17: ASP.NET Core Authorization
B18: 1.4.5 | C18: 2 | D18: 275 | F18: Verify that attribute or feature-based access control is used whereby the code checks the user's authorization for a feature/data item rather than just their role. Permissions should still be allocated using roles. ([C7](https://owasp.org/www-project-proactive-controls/#div-numbering)) | G18: Valid | H18: Program.cs: builder.Services.AddIdentity<AppUser, IdentityRole>() .AddEntityFrameworkStores<AppDbContext>() .AddDefaultTokenProviders(); builder.Services.AddAuthorization(options => { options.AddPolicy("CanImportProducts", policy => policy.RequireClaim("CanImport", "true")); }); app.UseAuthentication(); app.UseAuthorization(); ProductController.cs: [Authorize(Roles = nameof(UserType.Producer))] public class ProductController : ControllerBase { [HttpPost("import-from-file")] [Authorize(Policy = "CanImportProducts")] // controlo baseado em claim/atributo public IActionResult ImportProductsFromFile(IFormFile file) { // implementação omitida return Ok(); } } | I18: Utiliza-se o ASP.NET Core Identity para roles, complementado com validações específicas baseadas em claims (atributos) do utilizador para decisões de negócio. | J18: ASP.NET Core Identity
A19: Input and Output Architecture | B19: 1.5.1 | C19: 2 | D19: 1029 | F19: Verify that input and output requirements clearly define how to handle and process data based on type, content, and applicable laws, regulations, and other policy compliance. | G19: Valid | H19: ProductOfferController.cs: if(productOffer == null) return BadRequest(); catch(ArgumentException) { return BadRequest(); } | I19: Validação de dados e tratamento de erros implementados no controller para garantir dados corretos e conformidade. | J19: ASP.NET Core MVC
B20: 1.5.2 | C20: 2 | D20: 502 | F20: Verify that serialization is not used when communicating with untrusted clients. If this is not possible, ensure that adequate integrity controls (and possibly encryption if sensitive data is sent) are enforced to prevent deserialization attacks including object injection. | G20: Valid | H20: ProductOfferController.cs: [HttpPost] public IActionResult CreateProductOffer([FromBody] ProductOffer productOffer) { ... } Program.cs: builder.Services.AddControllers().AddJsonOptions(...) | I20: Desserialização JSON feita automaticamente via [FromBody] em modelos fortemente tipados, o que limita a superfície para ataques. Configuração padrão do System.Text.Json previne tipos arbitrários. | J20: System.Text.Json/ASP.NET Core
B21: 1.5.3 | C21: 2 | D21: 602 | F21: Verify that input validation is enforced on a trusted service layer. ([C5](https://owasp.org/www-project-proactive-controls/#div-numbering)) | G21: Valid | H21: if (ModelState.IsValid) em AccountController.cs; if (productOffer == null) em ProductOfferController.cs; if (subscription.ExpectedQuantity <= 0) em SubscriptionController.cs; [Authorize(Roles = nameof(UserType.Producer))] em vários controllers; if (!Enum.IsDefined(typeof(PaymentType), subscription.PaymentType)) em SubscriptionController.cs | I21: Validações e restrições feitas no backend, garantindo que todos os dados recebidos são verificados antes do processamento
B22: 1.5.4 | C22: 2 | D22: 116 | F22: Verify that output encoding occurs close to or by the interpreter for which it is intended. ([C4](https://www.owasp.org/index.php/OWASP_Proactive_Controls#tab=Formal_Numbering)) | G22: Valid | H22: return Ok(obj) em vários controllers; uso de JSON serialization padrão (System.Text.Json/Newtonsoft.Json) | I22: O backend apenas serializa dados para JSON, sem gerar HTML; a codificação de saída para XSS deve ser feita no frontend
A23: Cryptographic Architecture | B23: 1.6.1 | C23: 2 | D23: 320 | F23: Verify that there is an explicit policy for management of cryptographic keys and that a cryptographic key lifecycle follows a key management standard such as NIST SP 800-57. | G23: Non-valid | H23: Implementar o ASP.NET Core Data Protection com persistência das chaves no Azure Key Vault, garantindo que todas as chaves criptográficas usadas pela aplicação são geridas, protegidas e rotacionadas automaticamente conforme as melhores práticas do NIST. | I23: A clear key management policy reduces risks of exposure and misuse (risks 5.1 I, 3.3 I). It is recommended to follow NIST SP 800-57. | J23: Azure Key Vault, AWS KMS
B24: 1.6.2 | C24: 2 | D24: 320 | F24: Verify that consumers of cryptographic services protect key material and other secrets by using key vaults or API based alternatives. | G24: Non-valid | H24: Recomendada a externalização de todos os segredos sensíveis (como connection strings, passwords e chaves de API) para um serviço seguro, como o Azure Key Vault. A aplicação deve ser configurada para aceder a estes segredos de forma automática e segura, utilizando, por exemplo, o método builder.Configuration.AddAzureKeyVault(...) no ficheiro Program.cs | I24: Storing secrets in vaults prevents accidental exposure and attacks (risks 5.1 I, 3.3 I). | J24: Azure Key Vault, AWS Secrets Manager.
B25: 1.6.3 | C25: 2 | D25: 320 | F25: Verify that all keys and passwords are replaceable and are part of a well-defined process to re-encrypt sensitive data. | G25: Non-valid | H25: Necessário externalizar as chaves e segredos sensíveis para um cofre seguro, como o Azure Key Vault, permitindo a sua rotação sem necessidade de alterar o código. Além disso, deve ser implementado um processo formal e documentado para a rotação periódica dessas chaves e para a re-encriptação dos dados sensíveis sempre que uma chave for substituída. | I25: Key and password rotation processes mitigate the impact of compromise (risks 5.1 I, 3.3 I). | J25: Azure Key Vault, rotation scripts
B26: 1.6.4 | C26: 2 | D26: 320 | F26: Verify that the architecture treats client-side secrets--such as symmetric keys, passwords, or API tokens--as insecure and never uses them to protect or access sensitive data. | G26: Valid | H26: Autenticação e autorização feitas apenas no backend (ex: [Authorize], ASP.NET Identity) | I26: Não há segredos armazenados ou utilizados no frontend; toda a proteção de dados é feita de forma segura no backend. | J26: ASP.NET Identity
A27: Error, Logging and Auditing Architecture | B27: 1.7.1 | C27: 2 | D27: 1009 | F27: Verify that a common logging format and approach is used across the system. ([C9](https://owasp.org/www-project-proactive-controls/#div-numbering)) | G27: Non-valid | H27: Necessário adicionar e utilizar o serviço ILogger<T> do ASP.NET Core em todos os controladores e serviços do projeto, garantindo que todas as operações relevantes sejam registadas de forma estruturada e consistente. | I27: Using a common log format facilitates analysis and incident detection (risks 4.3 R, 5.1 I). | J27: Default logging in ASP.NET Core
B28: 1.7.2 | C28: 2 | F28: Verify that logs are securely transmitted to a preferably remote system for analysis, detection, alerting, and escalation. ([C9](https://owasp.org/www-project-proactive-controls/#div-numbering)) | G28: Non-valid | H28: Adicionar e configurar o Serilog (ou outro logger estruturado) para enviar logs via HTTPS para um sistema remoto (ex: Seq, ELK, Splunk), garantindo que o endpoint remoto está protegido e que toda a transmissão dos logs é cifrada. | I28: Securely transmitting logs to a remote system reduces the risk of tampering or loss of evidence (risks 4.3 R, 5.1 I). | J28: Solutions like ELK Stack, Azure Monitor, or remote syslog.
A29: Data Protection and Privacy Architecture | B29: 1.8.1 | C29: 2 | F29: Verify that all sensitive data is identified and classified into protection levels. | G29: Valid | H29: AppUser | I29: Passwords protegidas pelo ASP.NET Identity; autenticação e sessão via cookies seguros; dados pessoais em entidades como AppUser | J29: ASP.NET Identity /Documentation
B30: 1.8.2 | C30: 2 | F30: Verify that all protection levels have an associated set of protection requirements, such as encryption requirements, integrity requirements, retention, privacy and other confidentiality requirements, and that these are applied in the architecture. | G30: Valid | H30: Hashing de passwords pelo ASP.NET Identity; configuração de HTTPS no Program.cs | I30: Requisitos de cifragem e comunicação segura aplicados | J30: Identity/Documentation
A31: Communications Architecture | B31: 1.9.1 | C31: 2 | D31: 319 | F31: Verify the application encrypts communications between components, particularly when these components are in different containers, systems, sites, or cloud providers. ([C3](https://owasp.org/www-project-proactive-controls/#div-numbering)) | G31: Valid | H31: app.UseHttpsRedirection() no Program.cs; string de ligação da base de dados pode ser configurada com Encrypt=True | I31: HTTPS garante cifragem nas comunicações externas; ligação à base de dados deve ser ajustada para usar encriptação
B32: 1.9.2 | C32: 2 | D32: 295 | F32: Verify that application components verify the authenticity of each side in a communication link to prevent person-in-the-middle attacks. For example, application components should validate TLS certificates and chains. | G32: Valid | H32: Uso padrão de HTTPS no Kestrel/ASP.NET Core | I32: Certificados TLS são validados automaticamente
A33: Malicious Software Architecture | B33: 1.10.1 | C33: 2 | D33: 284 | F33: Verify that a source code control system is in use, with procedures to ensure that check-ins are accompanied by issues or change tickets. The source code control system should have access control and identifiable users to allow traceability of any changes. | G33: Valid | I33: O projeto utiliza Git com repositório remoto no GitHub, cada membro tem conta identificável, os commits podem ser associados a issues e todas as alterações passam por pull requests, garantindo rastreabilidade, revisão e controlo de acesso. | J33: GitHub
A34: Business Logic Architecture | B34: 1.11.1 | C34: 2 | D34: 1059 | F34: Verify the definition and documentation of all application components in terms of the business or security functions they provide. | G34: Valid | I34: API documentada automaticamente via Swagger; controllers organizados por função de negócio/segurança; README com documentação relevante sobre arquitetura, fluxos e componentes do sistema | J34: Swagger + Controllers + README(Relatorio)
B35: 1.11.2 | C35: 2 | D35: 362 | F35: Verify that all high-value business logic flows, including authentication, session management and access control, do not share unsynchronized state. | G35: Valid | H35: builder.Services.AddScoped<...>() e builder.Services.AddSingleton<EmailSender>() no Program.cs | I35: Autenticação e sessões isoladas por utilizador; serviços críticos registados como Scoped, evitando partilha de estado; Singletons não armazenam dados sensíveis | J35: ASP.NET Identity, Cookies, Injeção de Dependências
B36: 1.11.3 | C36: 2 | D36: 367 | F36: Verify that all high-value business logic flows, including authentication, session management and access control are thread safe and resistant to time-of-check and time-of-use race conditions. | G36: Valid | H36: Uso padrão de controllers e serviços Scoped no Program.cs; autenticação e permissões via ASP.NET Identity | I36: Endpoints críticos são isolados por request; não há partilha de estado mutável; framework garante thread-safety; monitorizar futuros acessos a recursos partilhados | J36: ASP.NET Core Controllers, Identity
A37: Secure File Upload Architecture | B37: 1.12.1 | C37: 2 | D37: 552 | F37: [DELETED, DUPLICATE OF 12.4.1] | G37: Not Applicable
B38: 1.12.2 | C38: 2 | D38: 646 | F38: Verify that user-uploaded files - if required to be displayed or downloaded from the application - are served by either octet stream downloads, or from an unrelated domain, such as a cloud file storage bucket. Implement a suitable Content Security Policy (CSP) to reduce the risk from XSS vectors or other attacks from the uploaded file. | G38: Valid | H38: Exemplo: return File(fileContent, contentType, fileName); em ProductController | I38: Ficheiros não são renderizados, apenas servidos como download com tipo MIME apropriado; não há preview direto
A39: API Architecture | F39: This is a placeholder for future architectural requirements. | G39: Not Applicable
A40: Configuration Architecture | B40: 1.14.1 | C40: 2 | D40: 923 | F40: Verify the segregation of components of differing trust levels through well-defined security controls, firewall rules, API gateways, reverse proxies, cloud-based security groups, or similar mechanisms. | G40: Valid | I40: Backend com endpoints bem definidos, permitindo aplicação de regras de firewall, proxies reversos e segmentação de rede em produção
...

Sheet Authentication
A1: Area | B1: # | C1: ASVS Level | D1: CWE | E1: NIST | F1: Verification Requirement | G1: Valid | H1: Source Code Reference | I1: Comment | J1: Tool Used
A2: Password Security -Pedro Vilarinho | B2: 2.1.1 | C2: 1 | D2: 521 | E2: 5.1.1.2 | F2: Verify that user set passwords are at least 12 characters in length (after multiple spaces are combined). ([C6](https://owasp.org/www-project-proactive-controls/#div-numbering)) | G2: Valid | H2: Program.cs:65 - options.Password.RequiredLength = 12; RegisterViewModel.cs:15 - [StringLength(128, MinimumLength = 12)] ChangePasswordViewModel.cs:12 - [StringLength(128, MinimumLength = 12)] | I2: Establishing a minimum password length of 12 characters is crucial to mitigate authentication-related threats, such as those identified with high severity in the DREAD analysis (#2, #7, #9, #10). Longer passwords significantly increase resistance against brute-force and dictionary attacks. This measure helps protect against "Identity spoofing to gain unauthorized access" and "Credential interception during transmission," which are critical threats in the AMAP system, especially considering access by different types of users (Managers, Producers, Co-Producers). | J2: Password validation libraries such as zxcvbn Password policy configuration in authentication frameworks Password strength validators on both frontend and backend
B3: 2.1.2 | C3: 1 | D3: 521 | E3: 5.1.1.2 | F3: Verify that passwords of at least 64 characters are permitted, and that passwords of more than 128 characters are denied. ([C6](https://owasp.org/www-project-proactive-controls/#div-numbering)) | G3: Valid | H3: Program.cs:162-169 - CustomPasswordValidator verifica password.Length > 128 RegisterViewModel.cs:15 - [StringLength(128, MinimumLength = 12)] ChangePasswordViewModel.cs:12 - [StringLength(128, MinimumLength = 12)] | I3: Allowing long passwords (up to 64 characters) while capping the maximum at 128 characters balances security and protection against DoS attacks. Longer passwords strengthen security against high-severity authentication-related threats identified in the DREAD analysis, such as "Identity spoofing to gain unauthorized access" (#7) and "Identity spoofing to bypass authentication" (#9). The upper limit of 128 characters protects against potential denial-of-service attacks based on extremely long passwords that could overwhelm the hashing process. | J3: ASP.NET Core Identity Framework - This is the authentication framework being used, which handles password validation through its configuration options and validators.
B4: 2.1.3 | C4: 1 | D4: 521 | E4: 5.1.1.2 | F4: Verify that password truncation is not performed. However, consecutive multiple spaces may be replaced by a single space. ([C6](https://owasp.org/www-project-proactive-controls/#div-numbering)) | G4: Valid | H4: Program.cs:173 - var normalizedPassword = Regex.Replace(password, @"\s+", " "); Program.cs:174-181 - Verifica normalizedPassword.Length < 12 após normalização | I4: Avoiding password truncation is essential to preserve the password’s entropy and strength as intended by the user. This practice prevents vulnerabilities related to various high-severity authentication threats identified in the DREAD analysis, such as "Identity spoofing to gain unauthorized access" (#7) and "Modification of credentials or tokens during transmission" (#8). Normalizing consecutive spaces into a single space is an acceptable compromise that avoids usability issues without significantly compromising security. Implementing this requirement is critical to protecting the accounts of all user profiles in the AMAP system (Managers, Producers, Co-Producers). | J4: Modern hashing algorithms that support long passwords (Argon2, bcrypt) Proper string processing for space normalization Automated tests to verify the correct behavior of the authentication system ASP.NET Core Identity for authentication management and password policies
B5: 2.1.4 | C5: 1 | D5: 521 | E5: 5.1.1.2 | F5: Verify that any printable Unicode character, including language neutral characters such as spaces and Emojis are permitted in passwords. | G5: Valid | H5: ASP.NET Core Identity already allows Unicode characters by default, so we don't need to add specific validation for this | I5: Allowing any printable Unicode character in passwords (including spaces and emojis) increases the available character space, making passwords stronger against brute-force attacks. This is particularly relevant considering the high-risk threats identified related to authentication and identity spoofing (threats #2, #7, #9, #10 in the DREAD list), such as "Identity spoofing to gain unauthorized access" and "Identity spoofing to bypass authentication. | J5: Password validation library that supports full Unicode Modern authentication framework (ASP.NET Identity)
B6: 2.1.5 | C6: 1 | D6: 620 | E6: 5.1.1.2 | F6: Verify users can change their password. | G6: Valid | H6: AccountController.cs:106-145 - Método ChangePassword implementado [HttpPost("change-password")] e [Authorize] para proteger o endpoint | I6: Allowing users to change their passwords is a fundamental security feature that mitigates several threats identified in the DREAD analysis. This capability is crucial in the event of credential compromise, directly relating to high-severity threats such as "Credential interception during transmission" (#10) and "Identity spoofing to gain unauthorized access" (#7). All user types in the AMAP system (Managers, Producers, and Co-Producers) should have this capability to maintain control over their accounts, especially considering the sensitive nature of financial and payment information managed on the platform. | J6: Password change functionality in the user interface Workflows to verify the current password before changing Email notifications for password changes to alert users about unauthorized changes ASP.NET Core Identity for authentication management and password policies
B7: 2.1.6 | C7: 1 | D7: 620 | E7: 5.1.1.2 | F7: Verify that password change functionality requires the user's current and new password. | G7: Valid | H7: ChangePasswordViewModel.cs:6-13 - Campos CurrentPassword e NewPassword obrigatórios AccountController.cs:125 - _userManager.ChangePasswordAsync(user, model.CurrentPassword, model.NewPassword) | I7: Requiring the current password during the password change process is a critical security measure that prevents unauthorized changes in case a session is compromised. This practice protects against several high-severity threats identified in the DREAD analysis, particularly "Privilege escalation from Co-Producer to Producer/Manager" (#18) and "Identity spoofing to gain unauthorized access" (#7). For the AMAP system, where different user profiles have access to different functionalities and sensitive data, this two-step verification is essential to ensure that only the legitimate user can change their password, even if an attacker gains temporary access to the authenticated session. | J7: Password change forms with current password validation Protection against brute force attacks on these interfaces Password change attempt logs for detecting suspicious activities ASP.NET Core Identity for authentication management and password policies
B8: 2.1.7 | C8: 1 | D8: 521 | E8: 5.1.1.2 | F8: Verify that passwords submitted during account registration, login, and password change are checked against a set of breached passwords either locally (such as the top 1,000 or 10,000 most common passwords which match the system's password policy) or using an external API. If using an API a zero knowledge proof or other mechanism should be used to ensure that the plain text password is not sent or used in verifying the breach status of the password. If the password is breached, the application must require the user to set a new non-breached password. ([C6](https://owasp.org/www-project-proactive-controls/#div-numbering)) | G8: Non-valid | I8: Verifying passwords against sets of compromised passwords is a crucial measure to protect against high-severity authentication threats identified in the DREAD analysis. This practice prevents the use of already leaked credentials, significantly reducing the risk of credential stuffing and brute-force attacks related to threats #7 "Identity spoofing to gain unauthorized access" and #9 "Identity spoofing to bypass authentication." For AMAP, where financial transactions and sensitive data from producers and consumers are involved, ensuring that passwords are not compromised is particularly important to protect against attacks that could lead to financial fraud or manipulation of offers. | J8: ASP.NET Core Identity for authentication management and password policies Have I Been Pwned (HIBP) service with k-anonymity implementation Local libraries for checking compromised passwords Zxcvbn or similar libraries for password strength evaluation Password verification APIs with zero-knowledge proof
B9: 2.1.8 | C9: 1 | D9: 521 | E9: 5.1.1.2 | F9: Verify that a password strength meter is provided to help users set a stronger password. | G9: Not Applicable | I9: Implementing a password strength meter provides immediate visual feedback to users, encouraging the creation of stronger and more diverse passwords. This interface feature helps mitigate authentication-related threats identified in the DREAD analysis, such as "Identity spoofing to gain unauthorized access" (#7) and "Identity spoofing to bypass authentication" (#9). For the AMAP system, where different profiles (Managers, Producers, Co-Producers) have access to critical functionalities and sensitive financial data, guiding users in creating strong passwords is essential for the overall security of the platform. | J9: ASP.NET Core Identity for password policies and validation Zxcvbn library for realistic password strength evaluation UI components for password strength meters Real-time feedback with password improvement suggestions
B10: 2.1.9 | C10: 1 | D10: 521 | E10: 5.1.1.2 | F10: Verify that there are no password composition rules limiting the type of characters permitted. There should be no requirement for upper or lower case or numbers or special characters. ([C6](https://owasp.org/www-project-proactive-controls/#div-numbering)) | G10: Non-valid | I10: Avoiding strict password composition rules favors longer and more memorable passwords over complex but short ones, aligning with modern security recommendations from NIST SP 800-63B. This approach helps prevent counterproductive behaviors such as writing down passwords or using predictable patterns. Considering the high-severity authentication-related threats in the DREAD analysis (such as #7 "Identity spoofing to gain unauthorized access" and #9 "Identity spoofing to bypass authentication"), the focus should be on the total entropy of the password, which is better achieved with increased length rather than arbitrary complexity rules. For AMAP, this policy enhances both the security and usability of the system. | J10: Authentication frameworks (like ASP.NET Core Identity) configured to verify only the minimum length Password strength meters based on real entropy (such as zxcvbn) Password policies aligned with NIST recommendations
B11: 2.1.10 | C11: 1 | D11: 263 | E11: 5.1.1.2 | F11: Verify that there are no periodic credential rotation or password history requirements. | G11: Valid | I11: The absence of mandatory periodic password rotation aligns with modern security guidelines (NIST SP 800-63B), which recognize that this practice often leads to risky behaviors such as sequential passwords or password writing. For the AMAP system, it is more effective to focus on detecting compromise (such as anomalous authentication) and provide mechanisms for changing passwords when necessary, rather than forcing arbitrary changes. This approach helps reduce threats identified in the DREAD analysis, such as "Identity spoofing to gain unauthorized access" (#7), without introducing practices that may lower overall security by encouraging weaker or more predictable passwords by users. | J11: Anomalous authentication detection systems Login notifications for new devices/locations Option for users to voluntarily change their passwords using ASP.NET Core Identity
B12: 2.1.11 | C12: 1 | D12: 521 | E12: 5.1.1.2 | F12: Verify that "paste" functionality, browser password helpers, and external password managers are permitted. | G12: Not Applicable | I12: Allowing the ability to paste passwords, browser password helpers, and external password managers is crucial to promote the use of strong and unique passwords. This practice aligns with modern security recommendations (NIST SP 800-63B) and mitigates various high-severity authentication threats identified in the DREAD analysis, such as "Identity spoofing to gain unauthorized access" (#7) and "Credential interception during transmission" (#10). For the AMAP system, with different types of users (Managers, Producers, Co-Producers) who need to keep credentials secure, enabling password manager usage encourages positive security behaviors, reducing the risk of password reuse and weak passwords. | J12: Proper configuration of password fields that do not block the "paste" functionality Support for browser autofill APIs Compatibility with popular password managers, alongside ASP.NET Core Identity
B13: 2.1.12 | C13: 1 | D13: 521 | E13: 5.1.1.2 | F13: Verify that the user can choose to either temporarily view the entire masked password, or temporarily view the last typed character of the password on platforms that do not have this as built-in functionality. | G13: Not Applicable | I13: Allowing temporary password visibility during typing strikes a balance between security and usability. This feature reduces input errors and user frustration while maintaining protection against onlookers ("shoulder surfing"). For AMAP, where different user profiles (Managers, Producers, Co-Producers) access the platform from various environments, this feature is important to avoid unnecessary account lockouts and reduce the tendency to create simple passwords out of fear of typing mistakes. This feature does not significantly compromise security when implemented correctly (temporary visibility, user-activated) and helps balance usability with protections against threats such as "Identity spoofing" (#2, #7, #9). | J13: Modern UI components for password fields with visibility toggle Implementing a timeout to automatically hide the password after brief exposure Visual feedback for the last typed character, in combination with ASP.NET Core Identity
A14: General Authenticator Security - Diogo Costa | B14: 2.2.1 | C14: 1 | D14: 307 | E14: 5.2.2, 5.1.1.2, 5.1.4.2, 5.1.5.2 | F14: Verify that anti-automation controls are effective at mitigating breached credential testing, brute force, and account lockout attacks. Such controls include blocking the most common breached passwords, soft lockouts, rate limiting, CAPTCHA, ever increasing delays between attempts, IP address restrictions, or risk-based restrictions such as location, first login on a device, recent attempts to unlock the account, or similar. Verify that no more than 100 failed attempts per hour is possible on a single account. | G14: Valid | H14: [Authorize] nos controllers | I14: Anti-automation controls are essential to protect against multiple high-severity threats identified in the DREAD analysis, particularly "Identity spoofing to gain unauthorized access" (#7) and "Identity spoofing to bypass authentication" (#9). For AMAP, where unauthorized access could lead to manipulation of listings, identity spoofing of producers or managers, and access to sensitive financial information, implementing defense-in-depth against automated attacks is critical. The combination of different techniques (rate limiting, increasing delays, CAPTCHA, temporary account lockouts) creates multiple barriers against brute force attacks without compromising system availability for legitimate users. | J14: ASP.NET Core Identity (for account lockout and multi-factor authentication) Brute force protection frameworks (like Fail2Ban) CAPTCHA/reCAPTCHA services Anomaly behavior detection systems Rate limiting libraries IP reputation systems Monitoring and alerting for suspicious login attempts
B15: 2.2.2 | C15: 1 | D15: 304 | E15: 5.2.10 | F15: Verify that the use of weak authenticators (such as SMS and email) is limited to secondary verification and transaction approval and not as a replacement for more secure authentication methods. Verify that stronger methods are offered before weak methods, users are aware of the risks, or that proper measures are in place to limit the risks of account compromise. | G15: Non-valid | I15: Limiting weak authenticators (SMS/email) to secondary verifications is crucial for AMAP, considering the high-severity threats identified in the DREAD analysis. This practice protects against "Manager identity spoofing" (#2), "Identity spoofing to gain unauthorized access" (#7), and "Spoofing of AMAP’s email system" (#27). For sensitive operations such as approving financial transactions, creating listings, and managing products, stronger authenticators should be the primary option. This approach is particularly important given AMAP’s system, where different access levels (Managers, Producers, CoProducers) handle sensitive financial and transactional information. | J15: ASP.NET Core Identity (for multi-factor authentication, including TOTP, WebAuthn) Risk analysis systems to determine when additional verification is required User education on risks associated with different authentication methods Authentication frameworks supporting multiple factors with varying levels of security
B16: 2.2.3 | C16: 1 | D16: 620 | F16: Verify that secure notifications are sent to users after updates to authentication details, such as credential resets, email or address changes, logging in from unknown or risky locations. The use of push notifications - rather than SMS or email - is preferred, but in the absence of push notifications, SMS or email is acceptable as long as no sensitive information is disclosed in the notification. | G16: Valid | I16: Secure notifications about changes to authentication details are essential for AMAP, considering several high-severity threats identified in the DREAD analysis, such as "Unauthorized change of payment information" (#17) and "Privilege escalation from CoProducer to Producer/Manager" (#18). For a system that manages financial information and transactions, alerting users about changes to their accounts allows for quick detection of compromise. A preference for push notifications over SMS/email enhances security, but any notification without sensitive data is better than none. This measure also helps mitigate risks related to "Denial of having made a subscription or payment" (#1) by creating visible audit trails for the user. | J16: ASP.NET Core Identity (for event-driven notifications when authentication details are changed) Secure push notification services Anomaly login detection systems Email/SMS templates without sensitive information Logs of sent notifications as part of the audit trail
B17: 2.2.4 | C17: 3 | D17: 308 | E17: 5.2.5 | F17: Verify impersonation resistance against phishing, such as the use of multi-factor authentication, cryptographic devices with intent (such as connected keys with a push to authenticate), or at higher AAL levels, client-side certificates. | G17: Valid | I17: Resistance to impersonation is critical for AMAP, given the multiple high-severity threats related to identity forgery identified in the DREAD analysis: "Impersonation of a Manager" (#2), "Impersonation for unauthorized access" (#7), "Impersonation of a Producer" (#26). For a system that manages financial transactions and allows managers and producers to create offers and manage resources, implementing phishing-resistant authenticators such as physical keys (FIDO2/WebAuthn) or app-based MFA is essential to prevent the compromise of high-privilege accounts. These mechanisms are particularly important for protecting the accounts of Managers and Producers who have extensive privileges in the system. | J17: FIDO2/WebAuthn authenticators (e.g., YubiKeys, Windows Hello) Authentication apps with intent verification (e.g., push to approve) Public Key Infrastructure (PKI) for client certificates Authentication frameworks supporting AAL2/AAL3 level authenticators ASP.NET Core Identity Framework for managing user authentication and integrating with phishing-resistant authenticators
B18: 2.2.5 | C18: 3 | D18: 319 | E18: 5.2.6 | F18: Verify that where a Credential Service Provider (CSP) and the application verifying authentication are separated, mutually authenticated TLS is in place between the two endpoints. | G18: Non-valid | I18: Mutual TLS authentication between the Credential Service Provider (CSP) and the AMAP application is essential to prevent several high-severity threats identified in the DREAD analysis, particularly "Modification of credentials or tokens during transmission" (#8) and "Interception of credentials during transmission" (#10). For a system like AMAP, which handles different access levels and sensitive financial information, ensuring secure and authenticated communication between distributed authentication components is critical. Mutual TLS (mTLS) verifies the identity of both endpoints, preventing man-in-the-middle attacks and ensuring that only authorized services can participate in the authentication flow. | J18: Public Key Infrastructure (PKI) for certificate management API Gateways with mTLS support Secure reverse proxies (e.g., Nginx, HAProxy) configured for mTLS Monitoring systems for certificate validity verification
B19: 2.2.6 | C19: 3 | D19: 308 | E19: 5.2.8 | F19: Verify replay resistance through the mandated use of One-time Passwords (OTP) devices, cryptographic authenticators, or lookup codes. | G19: Non-valid | I19: Resistance to replay attacks is essential for AMAP, considering the high-severity threats identified in the DREAD analysis, particularly "Impersonation for unauthorized access" (#7) and "Modification of credentials or tokens during transmission" (#8). To protect sensitive operations like payments, data modifications, and offer creation, implementing authenticators that generate one-time-use tokens (TOTP/HOTP) or cryptographic challenges prevents the reuse of captured credentials. This measure is especially important for Manager and Producer accounts that have privileged access in the system, mitigating the risk of session compromise or credential interception. | J19: TOTP/HOTP authentication apps (e.g., Google Authenticator, Microsoft Authenticator) FIDO2/WebAuthn authenticators with cryptographic challenges One-time code generation and verification systems Authentication frameworks supporting ephemeral tokens
B20: 2.2.7 | C20: 3 | D20: 308 | E20: 5.2.9 | F20: Verify intent to authenticate by requiring the entry of an OTP token or user-initiated action such as a button press on a FIDO hardware key. | G20: Non-valid | I20: Authentication intent verification is crucial for AMAP, considering multiple high-severity threats in the DREAD analysis, such as "Impersonation for unauthorized access" (8.0), "Impersonation to bypass authentication" (7.8), and "Credential interception during transmission" (7.8). Requiring an explicit user action (such as pressing a button on a FIDO key) or entering an OTP token confirms that the authentication is intentional and not automated by malware. This additional layer of protection is particularly important for Managers and Producers who have privileged access to critical system functions, such as payment and offer management. In addition to mitigating phishing risks, this requirement also helps fulfill GDPR obligations related to the protection of personal data. | J20: FIDO2/WebAuthn authenticators (e.g., YubiKey, security keys) TOTP authentication apps (e.g., Google Authenticator, Microsoft Authenticator) Authentication frameworks supporting MFA (e.g., Auth0, Firebase Authentication) WebAuthn integration libraries for web platforms
A21: Authenticator Lifecycle | B21: 2.3.1 | C21: 1 | D21: 330 | E21: 5.1.1.2, A. 3 | F21: Verify system generated initial passwords or activation codes SHOULD be securely randomly generated, SHOULD be at least 6 characters long, and MAY contain letters and numbers, and expire after a short period of time. These initial secrets must not be permitted to become the long term password. | G21: Not Applicable | I21: The implementation of initial passwords or activation codes generated by the system with secure characteristics is essential for AMAP, mitigating several high-severity threats from the DREAD analysis, such as "Impersonation of a Manager" (8.0) and "Impersonation for unauthorized access" (8.0). Ensuring that these temporary credentials are random, sufficiently complex, and expire quickly significantly reduces the window of opportunity for attacks during the registration or password reset process. Requiring users to change these initial passwords to permanent credentials chosen by the user is crucial to prevent unauthorized access, especially considering that privileged roles in the system (Managers and Producers) could be compromised. This practice also aligns with GDPR requirements to implement appropriate technical measures to protect personal data. | J21: Cryptographically Secure Pseudo-Random Number Generators (CSPRNG) Authentication frameworks supporting temporary passwords (e.g., ASP.NET Identity) Systems for automatic expiration of temporary passwords Password policy verification modules
B22: 2.3.2 | C22: 2 | D22: 308 | E22: 6.1.3 | F22: Verify that enrollment and use of user-provided authentication devices are supported, such as a U2F or FIDO tokens. | G22: Non-valid | I22: Supporting the integration and use of user-provided authentication devices, such as FIDO/U2F tokens, is highly relevant for AMAP due to several high-severity threats identified in the DREAD analysis, particularly "Impersonation for unauthorized access" (8.0), "Impersonation of a Manager" (8.0), and "Credential interception during transmission" (7.8). Physical security keys provide superior protection against phishing and credential theft attacks, as authentication depends on the possession of a physical device rather than credentials that can be compromised. For privileged roles like Managers and Producers, who have access to sensitive financial information and can modify offers or process payments, this additional layer of security is particularly valuable. Additionally, this requirement aligns with modern security recommendations and facilitates compliance with GDPR by implementing appropriate technical measures to protect personal data. | J22: WebAuthn/FIDO2 libraries (e.g., SimpleWebAuthn) FIDO security devices (e.g., YubiKey, Google Titan, etc.) Authentication frameworks supporting FIDO/U2F Credential management APIs for token registration and verification SDKs for integration with identity providers supporting FIDO ASP.NET Identity for user management and MFA integration (Note: ASP.NET Identity needs to be integrated with FIDO2/WebAuthn libraries for full support of FIDO/U2F tokens)
B23: 2.3.3 | C23: 2 | D23: 287 | E23: 6.1.4 | F23: Verify that renewal instructions are sent with sufficient time to renew time bound authenticators. | G23: Non-valid | I23: Ensuring that renewal instructions are sent in advance is essential for AMAP, especially to mitigate risks related to loss of access due to expired authentications. This is relevant to threats identified in the DREAD analysis, such as "Impersonation to bypass authentication" (7.8) and "Unauthorized access to control functionalities" (7.2). Timely renewal of temporal authenticators, such as tokens or certificates, reduces the risk of interruptions in legitimate access and prevents users from resorting to insecure practices like reusing compromised credentials. This practice also improves the user experience and aligns with security best practices, ensuring the continuity of strong authentication usage. | J23: Automated notification systems (email, SMS, push notifications) Authentication management APIs with token renewal support Certificate/authenticator expiration monitoring tools Authentication frameworks with support for renewal reminders (e.g., Auth0, Okta) ASP.NET Identity for managing authentication expiration and session renewal
A24: Credentials Storage - Pedro Costa | B24: 2.4.1 | C24: 2 | D24: 916 | E24: 5.1.1.2 | F24: Verify that passwords are stored in a form that is resistant to offline attacks. Passwords SHALL be salted and hashed using an approved one-way key derivation or password hashing function. Key derivation and password hashing functions take a password, a salt, and a cost factor as inputs when generating a password hash. ([C6](https://owasp.org/www-project-proactive-controls/#div-numbering)) | G24: Valid | H24: The Identity configuration is done in Program.cs, "builder.Services.AddIdentity<AppUser, IdentityRole>() .AddEntityFrameworkStores<AppDbContext>() .AddDefaultTokenProviders();" and the AppUser inherits from IdentityUser, that includes all the fields for a secure management of passwords. | I24: Storing passwords securely is essential for AMAP, considering threats such as "Credential interception during transmission" (7.8) and "Access to sensitive user information" (7.8). The use of approved key derivation or hashing functions, such as bcrypt, Argon2, or PBKDF2, with salting and a cost factor, protects against offline attacks, such as brute force or dictionary attacks, even if the hashes are compromised. This practice is crucial for protecting user accounts, especially those with elevated privileges, such as Managers and Producers. Additionally, secure password storage is a requirement under the GDPR to protect personal data and aligns with best security practices recommended by OWASP. | J24: Password hashing libraries (bcrypt, Argon2, PBKDF2) Authentication frameworks with support for secure hashing (ASP.NET Identity) Auditing tools to verify the security of password storage Security policy configuration for passwords (e.g., minimum length, complexity)
B25: 2.4.2 | C25: 2 | D25: 916 | E25: 5.1.1.2 | F25: Verify that the salt is at least 32 bits in length and be chosen arbitrarily to minimize salt value collisions among stored hashes. For each credential, a unique salt value and the resulting hash SHALL be stored. ([C6](https://owasp.org/www-project-proactive-controls/#div-numbering)) | G25: Valid | H25: In Program.cs we have "// Configure password hasher with explicit salt size and security parameters builder.Services.Configure<PasswordHasherOptions>(options => { // Salt size is 128 bits (16 bytes) - exceeds OWASP requirement of minimum 32 bits // Each user gets a unique random salt to prevent salt collisions options.IterationCount = 100000; // OWASP C6: PBKDF2 iteration count set to 100,000 as recommended options.CompatibilityMode = PasswordHasherCompatibilityMode.IdentityV3; // Uses PBKDF2 with HMAC-SHA256 });", that uses PasswordHasherCompatibilityMode, that specifies the format used for hashing passwords. | I25: Using a unique and random salt of at least 32 bits in length is essential for protecting passwords stored in AMAP against offline attacks, such as brute force and rainbow table attacks. This practice mitigates threats identified in the DREAD analysis, such as "Access to sensitive user information" (7.8) and "Credential interception during transmission" (7.8). A unique salt per credential ensures that identical hashes are not generated for the same passwords, even if they are used by different users. This approach aligns with best security practices and GDPR requirements for protecting personal data. | J25: Password hashing libraries with support for salting (bcrypt, Argon2, PBKDF2) Cryptographically secure random number generators (CSPRNG) for generating salt Authentication frameworks that implement automatic salting (e.g., ASP.NET Identity) Auditing tools to verify the uniqueness and length of stored salts
B26: 2.4.3 | C26: 2 | D26: 916 | E26: 5.1.1.2 | F26: Verify that if PBKDF2 is used, the iteration count SHOULD be as large as verification server performance will allow, typically at least 100,000 iterations. ([C6](https://owasp.org/www-project-proactive-controls/#div-numbering)) | G26: Valid | H26: In Program.cs we have "// Configure password hasher with explicit salt size and security parameters builder.Services.Configure<PasswordHasherOptions>(options => { // Salt size is 128 bits (16 bytes) - exceeds OWASP requirement of minimum 32 bits // Each user gets a unique random salt to prevent salt collisions options.IterationCount = 100000; // OWASP C6: PBKDF2 iteration count set to 100,000 as recommended options.CompatibilityMode = PasswordHasherCompatibilityMode.IdentityV3; // Uses PBKDF2 with HMAC-SHA256 });", and this code shows the implementation of PBKDF2 (through Identity), the iteration count of 100000 as recommended by OWASP and the explicit documentation of the security parameters. | I26: Using a high number of iterations in PBKDF2 is essential to increase resistance against offline attacks, such as brute force, by making the hashing process computationally expensive for attackers. This requirement is relevant for AMAP, considering threats such as "Access to sensitive user information" (7.8) and "Credential interception during transmission" (7.8). A minimum of 100,000 iterations is recommended, but the exact number should balance security and the performance of the authentication server. This practice aligns with best security practices and helps meet GDPR requirements for protecting personal data. | J26: Authentication frameworks that support configurable PBKDF2 (e.g., ASP.NET Identity) Benchmark tools to determine the ideal number of iterations based on server performance Regular audits to ensure the iteration count is up-to-date with current security standards
